Workbook

Sheet Assumptions
A1: TTF Gas Supply Stack Curve — Quantitative Framework
A2: All volumes in bcm/year unless otherwise stated. Blue cells are editable inputs.
A4: GLOBAL PARAMETERS
A5: Parameter | B5: Unit | C5: 2025 | D5: 2026 | E5: 2027 | F5: 2028 | G5: 2029 | H5: Source / Notes
A6: EUR/USD Exchange Rate | B6: EUR/USD | C6: 1.08 | D6: 1.1 | E6: 1.12 | F6: 1.12 | G6: 1.12 | H6: ECB forward curve
A7: EU ETS Carbon Price | B7: EUR/tCO2 | C7: 65 | D7: 72 | E7: 80 | F7: 88 | G7: 95 | H7: ICE EUA futures
A8: API2 Coal Price | B8: USD/t | C8: 110 | D8: 105 | E8: 100 | F8: 95 | G8: 90 | H8: ICE Rotterdam coal futures
A9: Brent Crude Oil Price | B9: USD/bbl | C9: 78 | D9: 75 | E9: 72 | F9: 70 | G9: 70 | H9: ICE Brent futures
A10: JKM LNG Price (Asia) | B10: USD/MMBtu | C10: 12.5 | D10: 11.8 | E10: 11 | F10: 10.5 | G10: 10 | H10: Platts JKM forward
A11: TTF-JKM Spread Threshold | B11: USD/MMBtu | C11: 1.5 | D11: 1.5 | E11: 1.5 | F11: 1.5 | G11: 1.5 | H11: Shipping cost differential
A12: Avg LNG Shipping Rate (US-EU) | B12: USD/MMBtu | C12: 0.8 | D12: 0.8 | E12: 0.75 | F12: 0.75 | G12: 0.7 | H12: Spark Commodities
A13: Avg LNG Shipping Rate (US-Asia) | B13: USD/MMBtu | C13: 2.2 | D13: 2.1 | E13: 2 | F13: 2 | G13: 1.9 | H13: Spark Commodities
A14: EU Storage Mandate Fill Target | B14: % | C14: 90 | D14: 90 | E14: 90 | F14: 90 | G14: 90 | H14: EU Regulation 2022/1032
A15: EU Storage Working Capacity | B15: bcm | C15: 110 | D15: 112 | E15: 114 | F15: 115 | G15: 115 | H15: GIE AGSI+
A16: European Gas Demand (Total) | B16: bcm | C16: 340 | D16: 335 | E16: 330 | F16: 325 | G16: 320 | H16: IEA/ENTSOG demand forecast
A17: of which Power Sector | B17: bcm | C17: 95 | D17: 92 | E17: 88 | F17: 85 | G17: 82 | H17: Model assumption
... A19: of which Residential/Commercial | B19: bcm | C19: 140 | D19: 140 | E19: 140 | F19: 140 | G19: 140 | H19: Weather-normalised

Sheet Norway Supply
A1: Norwegian Pipeline Gas Supply Model
A2: Field-by-field production, maintenance, and export pipeline allocation
A4: FIELD PRODUCTION CAPACITY (bcm/yr)
A5: Field / Facility | B5: Operator | C5: Unit | D5: 2025 | E5: 2026 | F5: 2027 | G5: 2028 | H5: 2029 | I5: Notes
A6: Troll | B6: Equinor | C6: bcm/yr | D6: 36 | E6: 35.5 | F6: 35 | G6: 34.5 | H6: 34 | I6: Phase 3 extension
A7: Ormen Lange | B7: Shell | C7: bcm/yr | D7: 14 | E7: 13.5 | F7: 13 | G7: 12.5 | H7: 12 | I7: Natural decline ~3.5%/yr
A8: Åsgard | B8: Equinor | C8: bcm/yr | D8: 7.5 | E8: 7.2 | F8: 6.9 | G8: 6.6 | H8: 6.3 | I8: Decline ~4%/yr
A9: Kristin | B9: Equinor | C9: bcm/yr | D9: 3.5 | E9: 3.3 | F9: 3.1 | G9: 2.9 | H9: 2.7 | I9: Decline ~6%/yr
A10: Kvitebjørn | B10: Equinor | C10: bcm/yr | D10: 5 | E10: 4.8 | F10: 4.6 | G10: 4.4 | H10: 4.2 | I10: Decline ~4%/yr
A11: Skarv | B11: Aker BP | C11: bcm/yr | D11: 4 | E11: 3.8 | F11: 3.6 | G11: 3.4 | H11: 3.2 | I11: Decline ~5%/yr
A12: Gjøa | B12: Neptune | C12: bcm/yr | D12: 2.5 | E12: 2.3 | F12: 2.1 | G12: 2 | H12: 1.9 | I12: Decline ~7%/yr
A13: Other fields (aggregate) | B13: Various | C13: bcm/yr | D13: 20 | E13: 19 | F13: 18 | G13: 17 | H13: 16 | I13: Weighted avg decline ~5%/yr
A14: GROSS FIELD CAPACITY | D14: =SUM(D6:D13) -> 92.5 | E14: =SUM(E6:E13) -> 89.4 | F14: =SUM(F6:F13) -> 86.3 | G14: =SUM(G6:G13) -> 83.3 | H14: =SUM(H6:H13) -> 80.3
A16: MAINTENANCE & OUTAGE DEDUCTIONS
A17: Deduction Factor | C17: Unit | D17: 2025 | E17: 2026 | F17: 2027 | G17: 2028 | H17: 2029 | I17: Notes
A18: Planned maintenance (summer) | C18: bcm/yr | D18: 8 | E18: 8.5 | F18: 9 | G18: 9.5 | H18: 10 | I18: Gassco calendar estimate
A19: Unplanned outage allowance | C19: bcm/yr | D19: 3 | E19: 3 | F19: 3 | G19: 3 | H19: 3 | I19: Historical avg ~3 bcm/yr
A20: Processing plant capacity constraint | C20: bcm/yr | D20: 1.5 | E20: 1.5 | F20: 1.5 | G20: 1.5 | H20: 1.5 | I20: Kollsnes/Kårstø bottleneck
A21: TOTAL DEDUCTIONS | D21: =SUM(D18:D20) -> 12.5 | E21: =SUM(E18:E20) -> 13 | F21: =SUM(F18:F20) -> 13.5 | G21: =SUM(G18:G20) -> 14 | H21: =SUM(H18:H20) -> 14.5
A23: NET DELIVERABLE NORWEGIAN SUPPLY | D23: =D14-D21 -> 80 | E23: =E14-E21 -> 76.4 | F23: =F14-F21 -> 72.8 | G23: =G14-G21 -> 69.3 | H23: =H14-H21 -> 65.8
A25: EXPORT PIPELINE ALLOCATION (bcm/yr)
A26: Pipeline Route | B26: Destination | C26: Capacity | D26: 2025 | E26: 2026 | F26: 2027 | G26: 2028 | H26: 2029 | I26: Utilisation %
A27: Europipe I | B27: Dornum, DE | C27: 18 | D27: 16.5 | E27: 16 | F27: 15.5 | G27: 15 | H27: 14.5 | I27: =D27/C27 -> 0.91666667
A28: Europipe II | B28: Dornum, DE | C28: 24 | D28: 22 | E28: 21.5 | F28: 21 | G28: 20.5 | H28: 20 | I28: =D28/C28 -> 0.91666667
A29: Franpipe | B29: Dunkerque, FR | C29: 20 | D29: 18 | E29: 17.5 | F29: 17 | G29: 16.5 | H29: 16 | I29: =D29/C29 -> 0.9
A30: Langeled | B30: Easington, UK | C30: 26 | D30: 14 | E30: 13.5 | F30: 13 | G30: 12.5 | H30: 12 | I30: =D30/C30 -> 0.53846154
A31: Norpipe | B31: Emden, DE | C31: 16 | D31: 6 | E31: 5.8 | F31: 5.6 | G31: 5.4 | H31: 5.2 | I31: =D31/C31 -> 0.375
A32: Zeepipe | B32: Zeebrugge, BE | C32: 15 | D32: 4 | E32: 3.8 | F32: 3.6 | G32: 3.4 | H32: 3.2 | I32: =D32/C32 -> 0.26666667

Sheet LNG Supply
A1: Global LNG Supply & European Allocation Model
A2: Project-level liquefaction, shipping, arbitrage, and regasification
A4: GLOBAL LIQUEFACTION CAPACITY BY PROJECT (MTPA)
A5: Project | B5: Country | C5: Status | D5: Nameplate | E5: 2025 | F5: 2026 | G5: 2027 | H5: 2028 | I5: 2029 | J5: Notes
A6: Sabine Pass T1-6 | B6: US | C6: Operating | D6: 30 | E6: 28.5 | F6: 28.5 | G6: 28.5 | H6: 28.5 | I6: 28.5 | J6: Cheniere, ~95% util
A7: Cameron T1-3 | B7: US | C7: Operating | D7: 15 | E7: 13.5 | F7: 13.5 | G7: 13.5 | H7: 13.5 | I7: 13.5 | J7: Sempra, ~90% util
A8: Freeport T1-3 | B8: US | C8: Operating | D8: 15 | E8: 13.5 | F8: 13.5 | G8: 13.5 | H8: 13.5 | I8: 13.5 | J8: ~90% util
A9: Corpus Christi S1-3 + SPL | B9: US | C9: Operating/Constr | D9: 25 | E9: 20 | F9: 22 | G9: 25 | H9: 25 | I9: 25 | J9: Stage 3 ramp-up
A10: Plaquemines P1-P2 | B10: US | C10: Construction | D10: 20 | E10: 5 | F10: 12 | G10: 18 | H10: 20 | I10: 20 | J10: Venture Global ramp
A11: Golden Pass T1-3 | B11: US | C11: Construction | D11: 18 | E11: 0 | F11: 4 | G11: 12 | H11: 16 | I11: 18 | J11: ExxonMobil/QE ramp
A12: Other US (Rio Grande etc) | B12: US | C12: Proposed/FID | D12: 25 | E12: 0 | F12: 0 | G12: 0 | H12: 5 | I12: 12 | J12: Subject to FID timing
A13: Qatar NFE (North Field East) | B13: Qatar | C13: Construction | D13: 32 | E13: 0 | F13: 8 | G13: 20 | H13: 32 | I13: 32 | J13: QatarEnergy mega-expansion
A14: Qatar NFS (North Field South) | B14: Qatar | C14: Construction | D14: 16 | E14: 0 | F14: 0 | G14: 0 | H14: 4 | I14: 12 | J14: Follow-on expansion
A15: Existing Qatar | B15: Qatar | C15: Operating | D15: 77 | E15: 77 | F15: 77 | G15: 77 | H15: 77 | I15: 77 | J15: Stable plateau
A16: Gorgon T1-3 | B16: Australia | C16: Operating | D16: 15.6 | E16: 14 | F16: 14 | G16: 13.5 | H16: 13.5 | I16: 13 | J16: Slight decline
A17: NW Shelf / Wheatstone / Ichthys | B17: Australia | C17: Operating | D17: 40 | E17: 36 | F17: 35.5 | G17: 35 | H17: 34.5 | I17: 34 | J17: Aggregate AU
... A23: Other global (Trinidad, Peru, etc) | B23: Various | C23: Operating | D23: 25 | E23: 22 | F23: 22 | G23: 22 | H23: 22 | I23: 22 | J23: Stable
A24: TOTAL GLOBAL LNG SUPPLY | E24: =SUM(E6:E23) -> 282.9 | F24: =SUM(F6:F23) -> 306.9 | G24: =SUM(G6:G23) -> 340.4 | H24: =SUM(H6:H23) -> 371.9 | I24: =SUM(I6:I23) -> 393.5
A26: LNG ALLOCATION TO EUROPE — ARBITRAGE MODEL
A27: Variable | B27: Unit | D27: 2025 | E27: 2026 | F27: 2027 | G27: 2028 | H27: 2029 | J27: Logic
A28: Global LNG Supply (from above) | B28: MTPA | D28: =D24 -> 0 | E28: =E24 -> 282.9 | F28: =F24 -> 306.9 | G28: =G24 -> 340.4 | H28: =H24 -> 371.9
A29: Global LNG Demand ex-Europe | B29: MTPA | D29: 285 | E29: 295 | F29: 310 | G29: 325 | H29: 340 | J29: Asia + LatAm + ME growth
A30: Available LNG for Europe (residual) | B30: MTPA | D30: =D28-D29 -> -285 | E30: =E28-E29 -> -12.1 | F30: =F28-F29 -> -3.1 | G30: =G28-G29 -> 15.4 | H30: =H28-H29 -> 31.9
A31: Conversion factor (MTPA to bcm) | B31: bcm/MTPA | D31: 1.379 | E31: 1.379 | F31: 1.379 | G31: 1.379 | H31: 1.379 | J31: Standard gas conversion
A32: Available LNG for Europe | B32: bcm/yr | D32: =D30*D31 -> -393.015 | E32: =E30*E31 -> -16.6859 | F32: =F30*F31 -> -4.2749 | G32: =G30*G31 -> 21.2366 | H32: =H30*H31 -> 43.9901
A33: European Regas Capacity | B33: bcm/yr | D33: 220 | E33: 230 | F33: 235 | G33: 240 | H33: 240 | J33: GIE + new FSRUs
A34: European Regas Utilisation Cap | B34: % | D34: 85 | E34: 85 | F34: 85 | G34: 85 | H34: 85 | J34: Technical max utilisation
A35: Max Deliverable LNG to Europe | B35: bcm/yr | D35: =MIN(D32,D33*D34) -> -393.015 | E35: =MIN(E32,E33*E34) -> -16.6859 | F35: =MIN(F32,F33*F34) -> -4.2749 | G35: =MIN(G32,G33*G34) -> 21.2366 | H35: =MIN(H32,H33*H34) -> 43.9901
A36: Arbitrage-Adjusted LNG to Europe | B36: bcm/yr | D36: =D35 -> -393.015 | E36: =E35 -> -16.6859 | F36: =F35 -> -4.2749 | G36: =G35 -> 21.2366 | H36: =H35 -> 43.9901 | J36: '=MIN(max deliverable, available) adjusted for ttf-jkm arb
A39: EUROPEAN REGASIFICATION TERMINALS (bcm/yr capacity)
A40: Terminal | B40: Country | C40: Type | D40: Capacity | E40: 2025 Util% | F40: 2026 Util% | G40: 2027 Util% | H40: 2028 Util% | I40: 2029 Util% | J40: Notes
A41: Gate Terminal | B41: NL | C41: Onshore | D41: 16 | E41: 0.75 | F41: 0.78 | G41: 0.8 | H41: 0.8 | I41: 0.8
A42: Grain Isle | B42: UK | C42: Onshore | D42: 19.5 | E42: 0.65 | F42: 0.68 | G42: 0.7 | H42: 0.72 | I42: 0.72
A43: Dunkerque | B43: FR | C43: Onshore | D43: 13 | E43: 0.7 | F43: 0.72 | G43: 0.75 | H43: 0.75 | I43: 0.75
A44: Zeebrugge | B44: BE | C44: Onshore | D44: 9 | E44: 0.6 | F44: 0.65 | G44: 0.68 | H44: 0.7 | I44: 0.7
A45: Montoir | B45: FR | C45: Onshore | D45: 10 | E45: 0.55 | F45: 0.58 | G45: 0.6 | H45: 0.62 | I45: 0.62
A46: Bilbao / Huelva / Barcelona / Cartagena | B46: ES | C46: Onshore | D46: 60 | E46: 0.4 | F46: 0.42 | G46: 0.45 | H46: 0.48 | I46: 0.5
A47: Sines / Figueira | B47: PT | C47: Onshore | D47: 7.6 | E47: 0.55 | F47: 0.58 | G47: 0.6 | H47: 0.62 | I47: 0.65
A48: Adriatic / Panigaglia / OLT / Piombino | B48: IT | C48: Mixed | D48: 28 | E48: 0.5 | F48: 0.55 | G48: 0.58 | H48: 0.6 | I48: 0.62
A49: Wilhelmshaven (FSRU + onshore) | B49: DE | C49: FSRU→Onshore | D49: 13.5 | E49: 0.6 | F49: 0.7 | G49: 0.75 | H49: 0.8 | I49: 0.85
...

Sheet Pipeline & Storage
A1: Other Pipeline Imports & Storage Model
A2: Russian, North African, Azerbaijani supply + EU storage dynamics
A4: PIPELINE IMPORTS BY ROUTE (bcm/yr)
A5: Route / Source | B5: Via | C5: Capacity | D5: 2025 | E5: 2026 | F5: 2027 | G5: 2028 | H5: 2029 | I5: Notes / Scenario
A6: Russia — TurkStream | B6: Turkey → SEE | C6: 15.75 | D6: 12 | E6: 10 | F6: 8 | G6: 6 | H6: 5 | I6: Base case: gradual decline
A7: Russia — Ukraine transit | B7: Ukraine → CEE | C7: 15 | D7: 0 | E7: 0 | F7: 0 | G7: 0 | H7: 0 | I7: Contract expired Dec 2024
A8: Russia — Other / Bypass | B8: Various | C8: 0 | D8: 0 | E8: 0 | F8: 0 | G8: 0 | H8: 0 | I8: Scenario placeholder
A9: Algeria — Transmed | B9: Tunisia → Italy | C9: 33.5 | D9: 22 | E9: 21 | F9: 20 | G9: 19 | H9: 18 | I9: Sonatrach allocation
A10: Algeria — Medgaz | B10: Direct → Spain | C10: 10.5 | D10: 8 | E10: 8 | F10: 8 | G10: 7.5 | H10: 7.5 | I10: Direct subsea
A11: Libya — Greenstream | B11: Direct → Italy | C11: 11 | D11: 3 | E11: 3 | F11: 3 | G11: 3 | H11: 3 | I11: Unreliable, political risk
A12: Azerbaijan — TAP/TANAP | B12: Turkey → Italy/Greece | C12: 10 | D12: 10 | E12: 10 | F12: 10 | G12: 10 | H12: 12 | I12: Expansion possible post-2028
A13: TOTAL OTHER PIPELINE IMPORTS | D13: =SUM(D6:D12) -> 55 | E13: =SUM(E6:E12) -> 52 | F13: =SUM(F6:F12) -> 49 | G13: =SUM(G6:G12) -> 45.5 | H13: =SUM(H6:H12) -> 45.5
A15: INDIGENOUS EU PRODUCTION (bcm/yr)
A16: Source | B16: Country | D16: 2025 | E16: 2026 | F16: 2027 | G16: 2028 | H16: 2029 | I16: Notes
A17: Dutch small fields | B17: NL | D17: 4.5 | E17: 3.8 | F17: 3.2 | G17: 2.7 | H17: 2.3 | I17: ~15% decline/yr
A18: UKCS (feeds NBP → TTF via IUK/BBL) | B18: UK | D18: 35 | E18: 33 | F18: 31 | G18: 29 | H18: 27 | I18: Terminal decline ~6%/yr
A19: Romania (inc Neptun Deep from ~2028) | B19: RO | D19: 5.5 | E19: 5.5 | F19: 5.5 | G19: 8 | H19: 10 | I19: Black Sea upside
A20: Denmark / Poland / Other EU | B20: Various | D20: 3 | E20: 2.8 | F20: 2.6 | G20: 2.4 | H20: 2.2 | I20: Declining baseline
A21: Biomethane / RNG | B21: EU-wide | D21: 3.5 | E21: 4.5 | F21: 5.5 | G21: 7 | H21: 9 | I21: REPowerEU target path
A22: TOTAL INDIGENOUS PRODUCTION | D22: =SUM(D17:D21) -> 51.5 | E22: =SUM(E17:E21) -> 49.6 | F22: =SUM(F17:F21) -> 47.8 | G22: =SUM(G17:G21) -> 49.1 | H22: =SUM(H17:H21) -> 50.5
A24: STORAGE DYNAMICS MODEL (bcm)
A25: Storage Parameter | B25: Unit | D25: 2025 | E25: 2026 | F25: 2027 | G25: 2028 | H25: 2029 | I25: Notes
A26: Working Gas Capacity | B26: bcm | D26: 110 | E26: 112 | F26: 114 | G26: 115 | H26: 115 | I26: GIE AGSI+
A27: Start-of-Year Inventory | B27: bcm | D27: 75 | E27: 70 | F27: 68 | G27: 66 | H27: 65 | I27: 1 Jan level
A28: Mandatory Fill Target (1 Nov) | B28: % | D28: 0.9 | E28: 0.9 | F28: 0.9 | G28: 0.9 | H28: 0.9 | I28: EU regulation
A29: Target Inventory (1 Nov) | B29: bcm | D29: =D28*D26 -> 99 | E29: =E28*E26 -> 100.8 | F29: =F28*F26 -> 102.6 | G29: =G28*G26 -> 103.5 | H29: =H28*H26 -> 103.5 | I29: Row above * capacity
A30: Required Net Injection (Jan-Oct) | B30: bcm | D30: =D29-D27 -> 24 | E30: =E29-E27 -> 30.8 | F30: =F29-F27 -> 34.6 | G30: =G29-G27 -> 37.5 | H30: =H29-H27 -> 38.5 | I30: Target minus start level
A31: Winter Withdrawal (Nov-Mar) | B31: bcm | D31: 55 | E31: 54 | F31: 53 | G31: 52 | H31: 51 | I31: Weather-normalised
A32: End-of-Winter Inventory | B32: bcm | D32: =D29-D31 -> 44 | E32: =E29-E31 -> 46.8 | F32: =F29-F31 -> 49.6 | G32: =G29-G31 -> 51.5 | H32: =H29-H31 -> 52.5 | I32: Target inv minus withdrawal
A33: Max Withdrawal Rate (at 90% full) | B33: mcm/day | D33: 1800 | E33: 1850 | F33: 1900 | G33: 1920 | H33: 1950 | I33: Aggregate system
A34: Max Withdrawal Rate (at 30% full) | B34: mcm/day | D34: 900 | E34: 920 | F34: 940 | G34: 950 | H34: 960 | I34: Non-linear deliverability

Sheet Supply Stack
A1: TTF Supply Stack & Market Clearing Model
A2: Merit-order aggregation of all supply sources vs demand to derive implied TTF price
A4: SUPPLY STACK — MERIT ORDER (bcm/yr, ranked by marginal cost)
A5: Supply Source | B5: Marginal Cost Proxy | C5: Unit | D5: 2025 | E5: 2026 | F5: 2027 | G5: 2028 | H5: 2029 | J5: Link
A6: 1. Norwegian Pipeline | B6: Lifting + transport | C6: EUR/MWh | D6: 6 | E6: 6.2 | F6: 6.4 | G6: 6.6 | H6: 6.8 | J6: 'Norway Supply' net output
A7: Volume (bcm) | C7: bcm | D7: 80.5 | E7: 77.4 | F7: 74.5 | G7: 71.6 | H7: 68.8 | J7: '='norway supply'!net row
A8: 2. Indigenous EU Production | B8: Production cost | C8: EUR/MWh | D8: 8 | E8: 8.5 | F8: 9 | G8: 9.5 | H8: 10 | J8: 'Pipeline & Storage' EU prod
A9: Volume (bcm) | C9: bcm | D9: 51.5 | E9: 49.6 | F9: 47.8 | G9: 49.1 | H9: 50.5 | J9: '='pipeline & storage'!eu total
A10: 3. Algerian Pipeline | B10: Contract price (oil-indexed) | C10: EUR/MWh | D10: 22 | E10: 21 | F10: 20 | G10: 19.5 | H10: 19 | J10: 'Pipeline & Storage'!Algeria rows
A11: Volume (bcm) | C11: bcm | D11: 30 | E11: 29 | F11: 28 | G11: 26.5 | H11: 25.5 | J11: Sum Transmed + Medgaz
A12: 4. Azerbaijani Pipeline | B12: Contract price | C12: EUR/MWh | D12: 24 | E12: 23.5 | F12: 23 | G12: 22.5 | H12: 22 | J12: 'Pipeline & Storage'!TAP row
A13: Volume (bcm) | C13: bcm | D13: 10 | E13: 10 | F13: 10 | G13: 10 | H13: 12 | J13: TAP/TANAP
A14: 5. Russian Pipeline (residual) | B14: Contract / political | C14: EUR/MWh | D14: 20 | E14: 20 | F14: 20 | G14: 20 | H14: 20 | J14: Scenario dependent
A15: Volume (bcm) | C15: bcm | D15: 12 | E15: 10 | F15: 8 | G15: 6 | H15: 5 | J15: TurkStream + residual
A16: 6. Storage Withdrawal | B16: Opportunity cost | C16: EUR/MWh | D16: 28 | E16: 29 | F16: 30 | G16: 31 | H16: 32 | J16: S/W spread implied
A17: Volume (bcm) | C17: bcm | D17: 55 | E17: 54 | F17: 53 | G17: 52 | H17: 51 | J17: Winter withdrawal
A18: 7. LNG (Marginal Supply) | B18: Netback / arbitrage | C18: EUR/MWh | D18: 32 | E18: 30 | F18: 28 | G18: 26 | H18: 25 | J18: TTF clearing price driver
A19: Volume (bcm) | C19: bcm | D19: 120 | E19: 130 | F19: 140 | G19: 148 | H19: 155 | J19: '='lng supply'!arb-adjusted output
A21: TOTAL SUPPLY (bcm/yr) | D21: =D7+D9+D11+D13+D15+D17+D19 -> 359 | E21: =E7+E9+E11+E13+E15+E17+E19 -> 360 | F21: =F7+F9+F11+F13+F15+F17+F19 -> 361.3 | G21: =G7+G9+G11+G13+G15+G17+G19 -> 363.2 | H21: =H7+H9+H11+H13+H15+H17+H19 -> 367.8
A22: TOTAL DEMAND (bcm/yr) | D22: 340 | E22: 335 | F22: 330 | G22: 325 | H22: 320
A23: SURPLUS / (DEFICIT) | D23: =D21-D22 -> 19 | E23: =E21-E22 -> 25 | F23: =F21-F22 -> 31.3 | G23: =G21-G22 -> 38.2 | H23: =H21-H22 -> 47.8
A25: IMPLIED TTF CLEARING PRICE
A26: LNG Marginal Cost (EUR/MWh) | D26: 32 | E26: 30 | F26: 28 | G26: 26 | H26: 25 | J26: Sets the clearing price when LNG is marginal
A27: Supply-Demand Balance Adjustment | D27: 2 | E27: 1 | F27: 0 | G27: -1 | H27: -2 | J27: Premium/(discount) for tightness
A28: Seasonality Adjustment (Winter Premium) | D28: 5 | E28: 5 | F28: 5 | G28: 5 | H28: 5 | J28: Q1 avg premium over annual
A29: Carbon Cost Pass-Through | D29: 3.5 | E29: 4 | F29: 4.5 | G29: 5 | H29: 5.5 | J29: EU ETS impact on switching price
A31: IMPLIED ANNUAL AVERAGE TTF (EUR/MWh) | D31: =D26+D27+D28+D29 -> 42.5 | E31: =E26+E27+E28+E29 -> 40 | F31: =F26+F27+F28+F29 -> 37.5 | G31: =G26+G27+G28+G29 -> 35 | H31: =H26+H27+H28+H29 -> 33.5
A32: IMPLIED TTF (USD/MMBtu equivalent) | D32: =D31*0.293*Assumptions!C6 -> 13.4487 | E32: =E31*0.293*Assumptions!D6 -> 12.892 | F32: =F31*0.293*Assumptions!E6 -> 12.306 | G32: =G31*0.293*Assumptions!F6 -> 11.4856 | H32: =H31*0.293*Assumptions!G6 -> 10.99336

Sheet Scenarios
A1: Scenario Analysis — TTF Price Sensitivity
A2: Key risk scenarios and their impact on the supply stack and clearing price
A4: SCENARIO DEFINITIONS
A5: Scenario | B5: Key Assumption Change | C5: Supply Impact (bcm) | D5: Demand Impact (bcm) | E5: TTF Impact (EUR/MWh) | F5: Probability | G5: Duration
A6: Base Case | B6: All assumptions as per model tabs | C6: 0 | D6: 0 | E6: 0 | F6: 50% | G6: —
A7: Cold Winter | B7: HDD 15% above normal | C7: 0 | D7: 25 | E7: 8 | F7: 15% | G7: 3-4 months
A8: Mild Winter | B8: HDD 15% below normal | C8: 0 | D8: -20 | E8: -6 | F8: 15% | G8: 3-4 months
A9: Full Russian Cutoff | B9: All Russian pipeline flows to zero | C9: -12 | D9: 0 | E9: 12 | F9: 10% | G9: Permanent
A10: Partial Russian Restoration | B10: TurkStream + new route = 30 bcm | C10: 18 | D10: 0 | E10: -15 | F10: 5% | G10: Structural
A11: Asian LNG Demand Surge | B11: JKM +$3/MMBtu, diverts 15MT from EU | C11: -20 | D11: 0 | E11: 10 | F11: 10% | G11: 6-12 months
A12: Major Norwegian Outage | B12: Troll/Nyhamna 2-month shutdown | C12: -6 | D12: 0 | E12: 15 | F12: 5% | G12: 2-3 months
A13: Accelerated Renewables | B13: Wind/solar +15% vs plan | C13: 0 | D13: -12 | E13: -4 | F13: 10% | G13: Structural
A14: US LNG Supply Disruption | B14: Hurricane / plant outage | C14: -8 | D14: 0 | E14: 8 | F14: 8% | G14: 1-3 months
A15: Qatar NFE Delay (1yr) | B15: Ramp pushed to 2028 | C15: -20 | D15: 0 | E15: 5 | F15: 15% | G15: 12 months
A16: Industrial Demand Recovery | B16: EU industrial rebound | C16: 0 | D16: 15 | E16: 6 | F16: 10% | G16: Structural
A17: Storage Mandate Raised to 95% | B17: Additional 5.5 bcm required | C17: 0 | D17: 5.5 | E17: 3 | F17: 5% | G17: Annual
A20: SENSITIVITY TABLE — TTF PRICE IMPACT (EUR/MWh per unit change)
A21: Driver | B21: Unit Change | C21: TTF Impact (EUR/MWh) | D21: Direction | E21: Confidence
A22: JKM Price | B22: +$1/MMBtu | C22: +3.0 to +4.0 | D22: Positive | E22: High
A23: EU ETS Carbon Price | B23: +€10/tCO2 | C23: +2.0 to +3.0 | D23: Positive | E23: High
A24: API2 Coal Price | B24: +$10/t | C24: -1.5 to -2.5 | D24: Negative (coal switch) | E24: Medium
A25: Norwegian Production | B25: -5 bcm/yr | C25: +3.0 to +5.0 | D25: Positive | E25: High
A26: Temperature (Winter) | B26: -1°C vs normal | C26: +2.0 to +3.5 | D26: Positive | E26: Medium
A27: Wind Generation | B27: -10% vs normal | C27: +1.5 to +2.5 | D27: Positive | E27: Medium
A28: EUR/USD Exchange Rate | B28: -0.05 (EUR weaker) | C28: +1.0 to +2.0 | D28: Positive (LNG cost up) | E28: Medium
A29: Storage Level (1 Nov) | B29: -10% vs target | C29: +4.0 to +8.0 | D29: Positive | E29: High
A30: Global LNG Supply | B30: -10 MTPA | C30: +5.0 to +8.0 | D30: Positive | E30: High
A31: Shipping Rates | B31: +$0.50/MMBtu | C31: +1.5 to +2.0 | D31: Positive | E31: Medium

Sheet Data Sources
A1: Data Sources & Feed Requirements
A2: Required data feeds to operationalise this model
A4: Data Feed | B4: Source | C4: Frequency | D4: Format | E4: Key Variables | F4: Cost / Access
A5: TTF & JKM Futures | B5: ICE / CME | C5: Real-time | D5: API / CSV | E5: Front-month, Cal strips, spreads | F5: Exchange subscription
A6: EU ETS Carbon Futures | B6: ICE Endex | C6: Real-time | D6: API | E6: EUA Dec contract | F6: Exchange subscription
A7: API2 Coal Futures | B7: ICE | C7: Real-time | D7: API | E7: Front-month, Cal strips | F7: Exchange subscription
A8: Brent Crude Futures | B8: ICE | C8: Real-time | D8: API | E8: Front-month, Cal strips | F8: Exchange subscription
A9: Norwegian Gas Flows | B9: Gassco / Entsog | C9: Hourly | D9: API / SFTP | E9: Nomination by exit point | F9: Free (Entsog TP)
A10: Norwegian Maintenance | B10: Gassco UMM | C10: As published | D10: RSS / API | E10: Plant, duration, capacity loss | F10: Free (REMIT UMM)
A11: EU Storage Levels | B11: GIE AGSI+ | C11: Daily | D11: API | E11: Country, facility, injection/withdrawal | F11: Free (API key)
A12: LNG Cargo Tracking | B12: Kpler / Vortexa | C12: Daily | D12: API | E12: Cargo, origin, destination, vessel | F12: Commercial subscription
A13: European Regas Nominations | B13: GIE ALSI | C13: Daily | D13: API | E13: Terminal send-out, utilisation | F13: Free (API key)
A14: Weather / HDD Forecasts | B14: ECMWF / DTN | C14: Daily+ | D14: API | E14: HDD by region, 15-day + seasonal | F14: Commercial subscription
A15: Wind / Solar Forecasts | B15: Entsoe / Elexon | C15: Hourly | D15: API | E15: Generation forecast by country | F15: Free (Entsoe TP)
... A20: LNG Shipping Rates | B20: Spark Commodities | C20: Daily | D20: API | E20: Spot rate, route-specific | F20: Commercial subscription
